An error occurred: HTTPConnectionPool(host='127.0.0.1', port=5000): Max retries exceeded with url: / (Caused by NewConnectionError('<urllib3.connection.HTTPConnection object at 0x0000021D1AB9F730>: Failed to establish a new connection: [WinError 10061] No connection could be made because the target machine actively refused it'))
Traceback: Traceback (most recent call last):
  File "C:\Users\Oreocromis\AppData\Local\Programs\Python\Python39\lib\site-packages\urllib3\connection.py", line 203, in _new_conn
    sock = connection.create_connection(
  File "C:\Users\Oreocromis\AppData\Local\Programs\Python\Python39\lib\site-packages\urllib3\util\connection.py", line 85, in create_connection
    raise err
  File "C:\Users\Oreocromis\AppData\Local\Programs\Python\Python39\lib\site-packages\urllib3\util\connection.py", line 73, in create_connection
    sock.connect(sa)
ConnectionRefusedError: [WinError 10061] No connection could be made because the target machine actively refused it

The above exception was the direct cause of the following exception:

Traceback (most recent call last):
  File "C:\Users\Oreocromis\AppData\Local\Programs\Python\Python39\lib\site-packages\urllib3\connectionpool.py", line 790, in urlopen
    response = self._make_request(
  File "C:\Users\Oreocromis\AppData\Local\Programs\Python\Python39\lib\site-packages\urllib3\connectionpool.py", line 496, in _make_request
    conn.request(
  File "C:\Users\Oreocromis\AppData\Local\Programs\Python\Python39\lib\site-packages\urllib3\connection.py", line 395, in request
    self.endheaders()
  File "C:\Users\Oreocromis\AppData\Local\Programs\Python\Python39\lib\http\client.py", line 1250, in endheaders
    self._send_output(message_body, encode_chunked=encode_chunked)
  File "C:\Users\Oreocromis\AppData\Local\Programs\Python\Python39\lib\http\client.py", line 1010, in _send_output
    self.send(msg)
  File "C:\Users\Oreocromis\AppData\Local\Programs\Python\Python39\lib\http\client.py", line 950, in send
    self.connect()
  File "C:\Users\Oreocromis\AppData\Local\Programs\Python\Python39\lib\site-packages\urllib3\connection.py", line 243, in connect
    self.sock = self._new_conn()
  File "C:\Users\Oreocromis\AppData\Local\Programs\Python\Python39\lib\site-packages\urllib3\connection.py", line 218, in _new_conn
    raise NewConnectionError(
urllib3.exceptions.NewConnectionError: <urllib3.connection.HTTPConnection object at 0x0000021D1AB9F730>: Failed to establish a new connection: [WinError 10061] No connection could be made because the target machine actively refused it

The above exception was the direct cause of the following exception:

Traceback (most recent call last):
  File "C:\Users\Oreocromis\AppData\Local\Programs\Python\Python39\lib\site-packages\requests\adapters.py", line 486, in send
    resp = conn.urlopen(
  File "C:\Users\Oreocromis\AppData\Local\Programs\Python\Python39\lib\site-packages\urllib3\connectionpool.py", line 844, in urlopen
    retries = retries.increment(
  File "C:\Users\Oreocromis\AppData\Local\Programs\Python\Python39\lib\site-packages\urllib3\util\retry.py", line 515, in increment
    raise MaxRetryError(_pool, url, reason) from reason  # type: ignore[arg-type]
urllib3.exceptions.MaxRetryError: HTTPConnectionPool(host='127.0.0.1', port=5000): Max retries exceeded with url: / (Caused by NewConnectionError('<urllib3.connection.HTTPConnection object at 0x0000021D1AB9F730>: Failed to establish a new connection: [WinError 10061] No connection could be made because the target machine actively refused it'))

During handling of the above exception, another exception occurred:

Traceback (most recent call last):
  File "e:\Tugas Kasar\vscode\test\Serial.py", line 34, in <module>
    response = requests.post(api_endpoint, json=payload)
  File "C:\Users\Oreocromis\AppData\Local\Programs\Python\Python39\lib\site-packages\requests\api.py", line 115, in post
    return request("post", url, data=data, json=json, **kwargs)
  File "C:\Users\Oreocromis\AppData\Local\Programs\Python\Python39\lib\site-packages\requests\api.py", line 59, in request
    return session.request(method=method, url=url, **kwargs)
  File "C:\Users\Oreocromis\AppData\Local\Programs\Python\Python39\lib\site-packages\requests\sessions.py", line 589, in request
    resp = self.send(prep, **send_kwargs)
  File "C:\Users\Oreocromis\AppData\Local\Programs\Python\Python39\lib\site-packages\requests\sessions.py", line 703, in send
    r = adapter.send(request, **kwargs)
  File "C:\Users\Oreocromis\AppData\Local\Programs\Python\Python39\lib\site-packages\requests\adapters.py", line 519, in send
    raise ConnectionError(e, request=request)
requests.exceptions.ConnectionError: HTTPConnectionPool(host='127.0.0.1', port=5000): Max retries exceeded with url: / (Caused by NewConnectionError('<urllib3.connection.HTTPConnection object at 0x0000021D1AB9F730>: Failed to establish a new connection: [WinError 10061] No connection could be made because the target machine actively refused it'))

An error occurred: HTTPConnectionPool(host='127.0.0.1', port=5000): Max retries exceeded with url: / (Caused by NewConnectionError('<urllib3.connection.HTTPConnection object at 0x0000021D1AC41130>: Failed to establish a new connection: [WinError 10061] No connection could be made because the target machine actively refused it'))
Traceback: Traceback (most recent call last):
  File "C:\Users\Oreocromis\AppData\Local\Programs\Python\Python39\lib\site-packages\urllib3\connection.py", line 203, in _new_conn
    sock = connection.create_connection(
  File "C:\Users\Oreocromis\AppData\Local\Programs\Python\Python39\lib\site-packages\urllib3\util\connection.py", line 85, in create_connection
    raise err
  File "C:\Users\Oreocromis\AppData\Local\Programs\Python\Python39\lib\site-packages\urllib3\util\connection.py", line 73, in create_connection
    sock.connect(sa)
ConnectionRefusedError: [WinError 10061] No connection could be made because the target machine actively refused it

The above exception was the direct cause of the following exception:

Traceback (most recent call last):
  File "C:\Users\Oreocromis\AppData\Local\Programs\Python\Python39\lib\site-packages\urllib3\connectionpool.py", line 790, in urlopen
    response = self._make_request(
  File "C:\Users\Oreocromis\AppData\Local\Programs\Python\Python39\lib\site-packages\urllib3\connectionpool.py", line 496, in _make_request
    conn.request(
  File "C:\Users\Oreocromis\AppData\Local\Programs\Python\Python39\lib\site-packages\urllib3\connection.py", line 395, in request
    self.endheaders()
  File "C:\Users\Oreocromis\AppData\Local\Programs\Python\Python39\lib\http\client.py", line 1250, in endheaders
    self._send_output(message_body, encode_chunked=encode_chunked)
  File "C:\Users\Oreocromis\AppData\Local\Programs\Python\Python39\lib\http\client.py", line 1010, in _send_output
    self.send(msg)
  File "C:\Users\Oreocromis\AppData\Local\Programs\Python\Python39\lib\http\client.py", line 950, in send
    self.connect()
  File "C:\Users\Oreocromis\AppData\Local\Programs\Python\Python39\lib\site-packages\urllib3\connection.py", line 243, in connect
    self.sock = self._new_conn()
  File "C:\Users\Oreocromis\AppData\Local\Programs\Python\Python39\lib\site-packages\urllib3\connection.py", line 218, in _new_conn
    raise NewConnectionError(
urllib3.exceptions.NewConnectionError: <urllib3.connection.HTTPConnection object at 0x0000021D1AC41130>: Failed to establish a new connection: [WinError 10061] No connection could be made because the target machine actively refused it

The above exception was the direct cause of the following exception:

Traceback (most recent call last):
  File "C:\Users\Oreocromis\AppData\Local\Programs\Python\Python39\lib\site-packages\requests\adapters.py", line 486, in send
    resp = conn.urlopen(
  File "C:\Users\Oreocromis\AppData\Local\Programs\Python\Python39\lib\site-packages\urllib3\connectionpool.py", line 844, in urlopen
    retries = retries.increment(
  File "C:\Users\Oreocromis\AppData\Local\Programs\Python\Python39\lib\site-packages\urllib3\util\retry.py", line 515, in increment
    raise MaxRetryError(_pool, url, reason) from reason  # type: ignore[arg-type]
urllib3.exceptions.MaxRetryError: HTTPConnectionPool(host='127.0.0.1', port=5000): Max retries exceeded with url: / (Caused by NewConnectionError('<urllib3.connection.HTTPConnection object at 0x0000021D1AC41130>: Failed to establish a new connection: [WinError 10061] No connection could be made because the target machine actively refused it'))

During handling of the above exception, another exception occurred:

Traceback (most recent call last):
  File "e:\Tugas Kasar\vscode\test\Serial.py", line 34, in <module>
    response = requests.post(api_endpoint, json=payload)
  File "C:\Users\Oreocromis\AppData\Local\Programs\Python\Python39\lib\site-packages\requests\api.py", line 115, in post
    return request("post", url, data=data, json=json, **kwargs)
  File "C:\Users\Oreocromis\AppData\Local\Programs\Python\Python39\lib\site-packages\requests\api.py", line 59, in request
    return session.request(method=method, url=url, **kwargs)
  File "C:\Users\Oreocromis\AppData\Local\Programs\Python\Python39\lib\site-packages\requests\sessions.py", line 589, in request
    resp = self.send(prep, **send_kwargs)
  File "C:\Users\Oreocromis\AppData\Local\Programs\Python\Python39\lib\site-packages\requests\sessions.py", line 703, in send
    r = adapter.send(request, **kwargs)
  File "C:\Users\Oreocromis\AppData\Local\Programs\Python\Python39\lib\site-packages\requests\adapters.py", line 519, in send
    raise ConnectionError(e, request=request)
requests.exceptions.ConnectionError: HTTPConnectionPool(host='127.0.0.1', port=5000): Max retries exceeded with url: / (Caused by NewConnectionError('<urllib3.connection.HTTPConnection object at 0x0000021D1AC41130>: Failed to establish a new connection: [WinError 10061] No connection could be made because the target machine actively refused it'))

An error occurred: HTTPConnectionPool(host='127.0.0.1', port=5000): Max retries exceeded with url: / (Caused by NewConnectionError('<urllib3.connection.HTTPConnection object at 0x0000021D1AC41A90>: Failed to establish a new connection: [WinError 10061] No connection could be made because the target machine actively refused it'))
Traceback: Traceback (most recent call last):
  File "C:\Users\Oreocromis\AppData\Local\Programs\Python\Python39\lib\site-packages\urllib3\connection.py", line 203, in _new_conn
    sock = connection.create_connection(
  File "C:\Users\Oreocromis\AppData\Local\Programs\Python\Python39\lib\site-packages\urllib3\util\connection.py", line 85, in create_connection
    raise err
  File "C:\Users\Oreocromis\AppData\Local\Programs\Python\Python39\lib\site-packages\urllib3\util\connection.py", line 73, in create_connection
    sock.connect(sa)
ConnectionRefusedError: [WinError 10061] No connection could be made because the target machine actively refused it

The above exception was the direct cause of the following exception:

Traceback (most recent call last):
  File "C:\Users\Oreocromis\AppData\Local\Programs\Python\Python39\lib\site-packages\urllib3\connectionpool.py", line 790, in urlopen
    response = self._make_request(
  File "C:\Users\Oreocromis\AppData\Local\Programs\Python\Python39\lib\site-packages\urllib3\connectionpool.py", line 496, in _make_request
    conn.request(
  File "C:\Users\Oreocromis\AppData\Local\Programs\Python\Python39\lib\site-packages\urllib3\connection.py", line 395, in request
    self.endheaders()
  File "C:\Users\Oreocromis\AppData\Local\Programs\Python\Python39\lib\http\client.py", line 1250, in endheaders
    self._send_output(message_body, encode_chunked=encode_chunked)
  File "C:\Users\Oreocromis\AppData\Local\Programs\Python\Python39\lib\http\client.py", line 1010, in _send_output
    self.send(msg)
  File "C:\Users\Oreocromis\AppData\Local\Programs\Python\Python39\lib\http\client.py", line 950, in send
    self.connect()
  File "C:\Users\Oreocromis\AppData\Local\Programs\Python\Python39\lib\site-packages\urllib3\connection.py", line 243, in connect
    self.sock = self._new_conn()
  File "C:\Users\Oreocromis\AppData\Local\Programs\Python\Python39\lib\site-packages\urllib3\connection.py", line 218, in _new_conn
    raise NewConnectionError(
urllib3.exceptions.NewConnectionError: <urllib3.connection.HTTPConnection object at 0x0000021D1AC41A90>: Failed to establish a new connection: [WinError 10061] No connection could be made because the target machine actively refused it

The above exception was the direct cause of the following exception:

Traceback (most recent call last):
  File "C:\Users\Oreocromis\AppData\Local\Programs\Python\Python39\lib\site-packages\requests\adapters.py", line 486, in send
    resp = conn.urlopen(
  File "C:\Users\Oreocromis\AppData\Local\Programs\Python\Python39\lib\site-packages\urllib3\connectionpool.py", line 844, in urlopen
    retries = retries.increment(
  File "C:\Users\Oreocromis\AppData\Local\Programs\Python\Python39\lib\site-packages\urllib3\util\retry.py", line 515, in increment
    raise MaxRetryError(_pool, url, reason) from reason  # type: ignore[arg-type]
urllib3.exceptions.MaxRetryError: HTTPConnectionPool(host='127.0.0.1', port=5000): Max retries exceeded with url: / (Caused by NewConnectionError('<urllib3.connection.HTTPConnection object at 0x0000021D1AC41A90>: Failed to establish a new connection: [WinError 10061] No connection could be made because the target machine actively refused it'))

During handling of the above exception, another exception occurred:

Traceback (most recent call last):
  File "e:\Tugas Kasar\vscode\test\Serial.py", line 34, in <module>
    response = requests.post(api_endpoint, json=payload)
  File "C:\Users\Oreocromis\AppData\Local\Programs\Python\Python39\lib\site-packages\requests\api.py", line 115, in post
    return request("post", url, data=data, json=json, **kwargs)
  File "C:\Users\Oreocromis\AppData\Local\Programs\Python\Python39\lib\site-packages\requests\api.py", line 59, in request
    return session.request(method=method, url=url, **kwargs)
  File "C:\Users\Oreocromis\AppData\Local\Programs\Python\Python39\lib\site-packages\requests\sessions.py", line 589, in request
    resp = self.send(prep, **send_kwargs)
  File "C:\Users\Oreocromis\AppData\Local\Programs\Python\Python39\lib\site-packages\requests\sessions.py", line 703, in send
    r = adapter.send(request, **kwargs)
  File "C:\Users\Oreocromis\AppData\Local\Programs\Python\Python39\lib\site-packages\requests\adapters.py", line 519, in send
    raise ConnectionError(e, request=request)
requests.exceptions.ConnectionError: HTTPConnectionPool(host='127.0.0.1', port=5000): Max retries exceeded with url: / (Caused by NewConnectionError('<urllib3.connection.HTTPConnection object at 0x0000021D1AC41A90>: Failed to establish a new connection: [WinError 10061] No connection could be made because the target machine actively refused it'))

An error occurred: HTTPConnectionPool(host='127.0.0.1', port=5000): Max retries exceeded with url: / (Caused by NewConnectionError('<urllib3.connection.HTTPConnection object at 0x0000021D1AC4B430>: Failed to establish a new connection: [WinError 10061] No connection could be made because the target machine actively refused it'))
Traceback: Traceback (most recent call last):
  File "C:\Users\Oreocromis\AppData\Local\Programs\Python\Python39\lib\site-packages\urllib3\connection.py", line 203, in _new_conn
    sock = connection.create_connection(
  File "C:\Users\Oreocromis\AppData\Local\Programs\Python\Python39\lib\site-packages\urllib3\util\connection.py", line 85, in create_connection
    raise err
  File "C:\Users\Oreocromis\AppData\Local\Programs\Python\Python39\lib\site-packages\urllib3\util\connection.py", line 73, in create_connection
    sock.connect(sa)
ConnectionRefusedError: [WinError 10061] No connection could be made because the target machine actively refused it

The above exception was the direct cause of the following exception:

Traceback (most recent call last):
  File "C:\Users\Oreocromis\AppData\Local\Programs\Python\Python39\lib\site-packages\urllib3\connectionpool.py", line 790, in urlopen
    response = self._make_request(
  File "C:\Users\Oreocromis\AppData\Local\Programs\Python\Python39\lib\site-packages\urllib3\connectionpool.py", line 496, in _make_request
    conn.request(
  File "C:\Users\Oreocromis\AppData\Local\Programs\Python\Python39\lib\site-packages\urllib3\connection.py", line 395, in request
    self.endheaders()
  File "C:\Users\Oreocromis\AppData\Local\Programs\Python\Python39\lib\http\client.py", line 1250, in endheaders
    self._send_output(message_body, encode_chunked=encode_chunked)
  File "C:\Users\Oreocromis\AppData\Local\Programs\Python\Python39\lib\http\client.py", line 1010, in _send_output
    self.send(msg)
  File "C:\Users\Oreocromis\AppData\Local\Programs\Python\Python39\lib\http\client.py", line 950, in send
    self.connect()
  File "C:\Users\Oreocromis\AppData\Local\Programs\Python\Python39\lib\site-packages\urllib3\connection.py", line 243, in connect
    self.sock = self._new_conn()
  File "C:\Users\Oreocromis\AppData\Local\Programs\Python\Python39\lib\site-packages\urllib3\connection.py", line 218, in _new_conn
    raise NewConnectionError(
urllib3.exceptions.NewConnectionError: <urllib3.connection.HTTPConnection object at 0x0000021D1AC4B430>: Failed to establish a new connection: [WinError 10061] No connection could be made because the target machine actively refused it

The above exception was the direct cause of the following exception:

Traceback (most recent call last):
  File "C:\Users\Oreocromis\AppData\Local\Programs\Python\Python39\lib\site-packages\requests\adapters.py", line 486, in send
    resp = conn.urlopen(
  File "C:\Users\Oreocromis\AppData\Local\Programs\Python\Python39\lib\site-packages\urllib3\connectionpool.py", line 844, in urlopen
    retries = retries.increment(
  File "C:\Users\Oreocromis\AppData\Local\Programs\Python\Python39\lib\site-packages\urllib3\util\retry.py", line 515, in increment
    raise MaxRetryError(_pool, url, reason) from reason  # type: ignore[arg-type]
urllib3.exceptions.MaxRetryError: HTTPConnectionPool(host='127.0.0.1', port=5000): Max retries exceeded with url: / (Caused by NewConnectionError('<urllib3.connection.HTTPConnection object at 0x0000021D1AC4B430>: Failed to establish a new connection: [WinError 10061] No connection could be made because the target machine actively refused it'))

During handling of the above exception, another exception occurred:

Traceback (most recent call last):
  File "e:\Tugas Kasar\vscode\test\Serial.py", line 34, in <module>
    response = requests.post(api_endpoint, json=payload)
  File "C:\Users\Oreocromis\AppData\Local\Programs\Python\Python39\lib\site-packages\requests\api.py", line 115, in post
    return request("post", url, data=data, json=json, **kwargs)
  File "C:\Users\Oreocromis\AppData\Local\Programs\Python\Python39\lib\site-packages\requests\api.py", line 59, in request
    return session.request(method=method, url=url, **kwargs)
  File "C:\Users\Oreocromis\AppData\Local\Programs\Python\Python39\lib\site-packages\requests\sessions.py", line 589, in request
    resp = self.send(prep, **send_kwargs)
  File "C:\Users\Oreocromis\AppData\Local\Programs\Python\Python39\lib\site-packages\requests\sessions.py", line 703, in send
    r = adapter.send(request, **kwargs)
  File "C:\Users\Oreocromis\AppData\Local\Programs\Python\Python39\lib\site-packages\requests\adapters.py", line 519, in send
    raise ConnectionError(e, request=request)
requests.exceptions.ConnectionError: HTTPConnectionPool(host='127.0.0.1', port=5000): Max retries exceeded with url: / (Caused by NewConnectionError('<urllib3.connection.HTTPConnection object at 0x0000021D1AC4B430>: Failed to establish a new connection: [WinError 10061] No connection could be made because the target machine actively refused it'))

An error occurred: HTTPConnectionPool(host='127.0.0.1', port=5000): Max retries exceeded with url: / (Caused by NewConnectionError('<urllib3.connection.HTTPConnection object at 0x0000021D1AC41250>: Failed to establish a new connection: [WinError 10061] No connection could be made because the target machine actively refused it'))
Traceback: Traceback (most recent call last):
  File "C:\Users\Oreocromis\AppData\Local\Programs\Python\Python39\lib\site-packages\urllib3\connection.py", line 203, in _new_conn
    sock = connection.create_connection(
  File "C:\Users\Oreocromis\AppData\Local\Programs\Python\Python39\lib\site-packages\urllib3\util\connection.py", line 85, in create_connection
    raise err
  File "C:\Users\Oreocromis\AppData\Local\Programs\Python\Python39\lib\site-packages\urllib3\util\connection.py", line 73, in create_connection
    sock.connect(sa)
ConnectionRefusedError: [WinError 10061] No connection could be made because the target machine actively refused it

The above exception was the direct cause of the following exception:

Traceback (most recent call last):
  File "C:\Users\Oreocromis\AppData\Local\Programs\Python\Python39\lib\site-packages\urllib3\connectionpool.py", line 790, in urlopen
    response = self._make_request(
  File "C:\Users\Oreocromis\AppData\Local\Programs\Python\Python39\lib\site-packages\urllib3\connectionpool.py", line 496, in _make_request
    conn.request(
  File "C:\Users\Oreocromis\AppData\Local\Programs\Python\Python39\lib\site-packages\urllib3\connection.py", line 395, in request
    self.endheaders()
  File "C:\Users\Oreocromis\AppData\Local\Programs\Python\Python39\lib\http\client.py", line 1250, in endheaders
    self._send_output(message_body, encode_chunked=encode_chunked)
  File "C:\Users\Oreocromis\AppData\Local\Programs\Python\Python39\lib\http\client.py", line 1010, in _send_output
    self.send(msg)
  File "C:\Users\Oreocromis\AppData\Local\Programs\Python\Python39\lib\http\client.py", line 950, in send
    self.connect()
  File "C:\Users\Oreocromis\AppData\Local\Programs\Python\Python39\lib\site-packages\urllib3\connection.py", line 243, in connect
    self.sock = self._new_conn()
  File "C:\Users\Oreocromis\AppData\Local\Programs\Python\Python39\lib\site-packages\urllib3\connection.py", line 218, in _new_conn
    raise NewConnectionError(
urllib3.exceptions.NewConnectionError: <urllib3.connection.HTTPConnection object at 0x0000021D1AC41250>: Failed to establish a new connection: [WinError 10061] No connection could be made because the target machine actively refused it

The above exception was the direct cause of the following exception:

Traceback (most recent call last):
  File "C:\Users\Oreocromis\AppData\Local\Programs\Python\Python39\lib\site-packages\requests\adapters.py", line 486, in send
    resp = conn.urlopen(
  File "C:\Users\Oreocromis\AppData\Local\Programs\Python\Python39\lib\site-packages\urllib3\connectionpool.py", line 844, in urlopen
    retries = retries.increment(
  File "C:\Users\Oreocromis\AppData\Local\Programs\Python\Python39\lib\site-packages\urllib3\util\retry.py", line 515, in increment
    raise MaxRetryError(_pool, url, reason) from reason  # type: ignore[arg-type]
urllib3.exceptions.MaxRetryError: HTTPConnectionPool(host='127.0.0.1', port=5000): Max retries exceeded with url: / (Caused by NewConnectionError('<urllib3.connection.HTTPConnection object at 0x0000021D1AC41250>: Failed to establish a new connection: [WinError 10061] No connection could be made because the target machine actively refused it'))

During handling of the above exception, another exception occurred:

Traceback (most recent call last):
  File "e:\Tugas Kasar\vscode\test\Serial.py", line 34, in <module>
    response = requests.post(api_endpoint, json=payload)
  File "C:\Users\Oreocromis\AppData\Local\Programs\Python\Python39\lib\site-packages\requests\api.py", line 115, in post
    return request("post", url, data=data, json=json, **kwargs)
  File "C:\Users\Oreocromis\AppData\Local\Programs\Python\Python39\lib\site-packages\requests\api.py", line 59, in request
    return session.request(method=method, url=url, **kwargs)
  File "C:\Users\Oreocromis\AppData\Local\Programs\Python\Python39\lib\site-packages\requests\sessions.py", line 589, in request
    resp = self.send(prep, **send_kwargs)
  File "C:\Users\Oreocromis\AppData\Local\Programs\Python\Python39\lib\site-packages\requests\sessions.py", line 703, in send
    r = adapter.send(request, **kwargs)
  File "C:\Users\Oreocromis\AppData\Local\Programs\Python\Python39\lib\site-packages\requests\adapters.py", line 519, in send
    raise ConnectionError(e, request=request)
requests.exceptions.ConnectionError: HTTPConnectionPool(host='127.0.0.1', port=5000): Max retries exceeded with url: / (Caused by NewConnectionError('<urllib3.connection.HTTPConnection object at 0x0000021D1AC41250>: Failed to establish a new connection: [WinError 10061] No connection could be made because the target machine actively refused it'))

